Workbook

Sheet Painel
B1: Viagem pelo Continente — rolagem do período
B2: 1) Escolha a situação nas células amarelas. 2) Digite os dados que você rolou na coluna 'Seu dado' — ou deixe em branco e a planilha rola sozinha (F9 rerrola).
B4: 1. Situação | L4: Cálculos (não editar)
B6: Área | C6: Média | D6: ="Evento com d20 ≥ "&M6&" · Intensidade "&TEXT(M20,"+0;-0;+0")&" · "&INDEX(Ajustes!$F$6:$F$9,MATCH(C6,Ajustes!$B$6:$B$9,0)) | L6: Limiar d20 | M6: =INDEX(Ajustes!$D$6:$D$9,MATCH($C$6,Ajustes!$B$6:$B$9,0))
B7: Período | C7: Noite | D7: ="Mod. d20 "&TEXT(M7,"+0;-0;+0")&" · Mod. d100 "&TEXT(M8,"+0;-0;+0")&" · "&INDEX(Ajustes!$G$13:$G$16,MATCH(C7,Ajustes!$B$13:$B$16,0)) | L7: Mod período d20 | M7: =INDEX(Ajustes!$D$13:$D$16,MATCH($C$7,Ajustes!$B$13:$B$16,0))
B8: Estação | C8: Outono | D8: ="Define a tabela de clima." | L8: Mod período d100 | M8: =INDEX(Ajustes!$E$13:$E$16,MATCH($C$7,Ajustes!$B$13:$B$16,0))
B9: Terreno | C9: Floresta | D9: =INDEX(Ajustes!$C$35:$C$39,MATCH(C9,Ajustes!$B$35:$B$39,0)) | L9: Mod situação d20 | M9: =INDEX(Ajustes!$D$21:$D$24,MATCH($C$10,Ajustes!$B$21:$B$24,0))
B10: Situação do grupo | C10: Na estrada | D10: ="Mod. d20 "&TEXT(M9,"+0;-0;+0")&" · "&INDEX(Ajustes!$C$21:$C$24,MATCH(C10,Ajustes!$B$21:$B$24,0)) | L10: Linha clima | M10: =MIN(11,COUNTIF(Clima!$T$6:$T$16,"<"&E14)+1)
L11: Mod clima d20 | M11: =INDEX(Clima!$K$6:$K$16,M10)
B12: 2. Rolagens | L12: Mod clima d100 | M12: =INDEX(Clima!$L$6:$L$16,M10)
B13: Etapa | C13: Dado | D13: Seu dado (opcional) | E13: Usado | F13: Resultado | G13: Detalhe | L13: Total d20 | M13: =E15+M7+M9+M11
B14: Clima (1× por dia) | C14: d100 | E14: =IF(D14="",RANDBETWEEN(1,100),D14) | F14: =INDEX(Clima!$B$6:$B$16,M10) | G14: =INDEX(Clima!$M$6:$M$16,M10) | L14: Acontece? | M14: =M13>=M6
B15: Acontece algo? | C15: d20 | E15: =IF(D15="",RANDBETWEEN(1,20),D15) | F15: =IF(M14,"SIM — algo acontece","Nada acontece") | G15: ="d20 "&E15&" + mods "&TEXT(M7+M9+M11,"+0;-0;+0")&" = "&M13&" (precisa de "&M6&"+)" | L15: d100 ajustado | M15: =MAX(1,MIN(100,E16+M8+M12))
B16: Tipo de evento | C16: d100 | E16: =IF(D16="",RANDBETWEEN(1,100),D16) | F16: =IF(M14,INDEX('Tipo de evento'!$B$6:$B$13,M16),"—") | G16: =IF(M14,"d100 "&E16&" + mods "&TEXT(M8+M12,"+0;-0;+0")&" = "&M15&IF(M17="—",""," · envolve: "&M17),"—") | L16: Linha tipo | M16: =MIN(8,COUNTIF('Tipo de evento'!$T$6:$T$13,"<"&M15)+1)
B17: Qual evento | C17: d6 | E17: =IF(D17="",RANDBETWEEN(1,6),D17) | F17: =IF(M18=0,"—",INDEX(Eventos!$D$1:$D$52,M18)) | G17: =IF(M18=0,"—",INDEX(Eventos!$E$1:$E$52,M18)&" (melhor: "&INDEX(Eventos!$H$1:$H$52,M18)&")") | L17: Categoria criatura | M17: =IF(M14,INDEX('Tipo de evento'!$K$6:$K$13,M16),"—")
B18: Criatura | C18: d100 | E18: =IF(D18="",RANDBETWEEN(1,100),D18) | F18: =IF(M19=0,"—",INDEX(Criaturas!$B$6:$B$38,M19)) | G18: =IF(M19=0,"—","NP "&INDEX(Criaturas!$E$6:$E$38,M19)&" · "&INDEX(Criaturas!$H$6:$H$38,M19)&" · ficha: "&INDEX(Criaturas!$C$6:$C$38,M19)) | L18: Linha evento | M18: =IF(M14,IFERROR(MATCH(F16&"|"&E17,Eventos!$A$1:$A$52,0),0),0)
B19: Intensidade | C19: d6 | E19: =IF(D19="",RANDBETWEEN(1,6),D19) | F19: =IF(M19=0,"—",INDEX(Intensidade!$C$5:$C$12,M21)) | G19: =IF(M19=0,"—","d6 "&E19&" "&TEXT(M20,"+0;-0;+0")&" = "&M21&" · "&INDEX(Intensidade!$D$5:$D$12,M21)) | L19: Linha criatura | M19: =IF(M17="—",0,IF(MAX(Criaturas!$Q$6:$Q$38)=0,0,MIN(33,COUNTIF(Criaturas!$Q$6:$Q$38,"<"&E18/100*MAX(Criaturas!$Q$6:$Q$38))+1)))
L20: Mod intensidade | M20: =INDEX(Ajustes!$E$6:$E$9,MATCH($C$6,Ajustes!$B$6:$B$9,0))
B21: 3. Para narrar | L21: Intensidade | M21: =MAX(1,MIN(8,E19+M20))
B22: Clima | C22: =F14&": "&INDEX(Clima!$M$6:$M$16,M10)&" Regra: "&INDEX(Clima!$N$6:$N$16,M10)
B23: Cena | C23: =IF(M18=0,"Nada relevante neste período. Descreva a paisagem e o clima e avance a viagem.",F17&": "&INDEX(Eventos!$E$1:$E$52,M18))
B24: Opções do jogador | C24: =IF(M18=0,"—",INDEX(Eventos!$F$1:$F$52,M18))
B25: Nota do mestre | C25: =IF(M18=0,"—",INDEX(Eventos!$G$1:$G$52,M18))
B26: Criatura | C26: =IF(M19=0,"—",IF(F16="Pista / presságio","Quem deixou o sinal: ","")&F18&" — "&INDEX(Criaturas!$M$6:$M$38,M19))
B27: Intensidade | C27: =IF(M19=0,"—",IF(F16="Pista / presságio","Pista: a criatura não aparece agora. Se o grupo seguir o rastro, use: ","")&F19&" — "&INDEX(Intensidade!$E$5:$E$12,M21))
B28: Regras fixas | C28: Máx. 1 combate relevante por dia de viagem · Nunca contradiga a missão (se ela diz leshen, não vira carniçal) · Resultado que não faz sentido no lugar: role de novo ou escolha o mais próximo · Clima: 1d6 na troca de período, 6 = muda.

Sheet Como usar
B1: Como usar — eventos de viagem (The Witcher × M&M 3e)
B2: Use no Painel. Role uma vez por período (manhã, tarde, noite, madrugada) em que o grupo viaja ou acampa.
B4: Passo | C4: O que fazer | D4: Dado | E4: Detalhes
B5: 0 | C5: Situação | D5: — | E5: No Painel, escolha Área (Tranquila, Média, Perigosa, Mortal), Período, Estação, Terreno e Situação do grupo.
B6: 1 | C6: Clima | D6: d100 | E6: No início do dia. Tabela pela estação (aba Clima). Na troca de período role 1d6: no 6 o clima muda. Neblina deixa eventos mais prováveis e estranhos; tempestade, frio e nevasca esvaziam a estrada.
B7: 2 | C7: Acontece algo? | D7: d20 | E7: d20 + mod. do período + mod. da situação + mod. do clima ≥ limiar da área (Tranquila 17, Média 14, Perigosa 11, Mortal 8). Se não, só descreva a viagem.
B8: 3 | C8: Tipo de evento | D8: d100 | E8: d100 + mod. do período e do clima, na coluna da área (aba Tipo de evento). Manhã puxa para o cotidiano; madrugada puxa para monstros e sobrenatural.
B9: 4 | C9: Qual evento | D9: d6 | E9: d6 dentro do tipo (aba Eventos). Se não combinar com o período ou o lugar, role de novo.
B10: 5 | C10: Criatura | D10: d100 | E10: Só se o tipo envolve criatura (Pista, Humanos hostis, Fera, Monstro, Sobrenatural). A aba Criaturas filtra pela categoria e pesa por área, período e terreno. Em Pista, é quem deixou o sinal.
B11: 6 | C11: Intensidade | D11: d6 | E11: d6 + mod. da área (−1 a +2). De 'só sinais' a 'emboscada + complicação' (aba Intensidade).
B13: Regras fixas
B14: • Personagem solo: resultado alto vira pressão, perseguição, obstáculo ou fuga, não mais inimigos.
B15: • Coerência: nunca contradiga a missão. Se ela diz que há um leshen, a tabela não o transforma em carniçal.
B16: • Ritmo: no máximo 1 combate relevante por dia de viagem, salvo viagem deliberadamente perigosa.
B17: • M&M 3e: NP e fichas base são ponto de partida; ajuste ao personagem. Fichas em dados/bestiario/fantasia; humanos saem do gerador de NPC (arquétipos de fantasia).
B18: • Sem planilha à mão: as abas Clima, Tipo de evento, Eventos e Intensidade funcionam impressas, lendo as faixas da área e estação.
B20: Cores
C21: Amarelo com texto azul: pode editar (escolhas, dados rolados, pesos, modificadores).
C22: Bege: resultado calculado. Texto cinza: cálculos auxiliares, não edite.

Sheet Ajustes
B1: Ajustes da viagem
B2: Células amarelas com texto azul podem ser editadas. Painel, Criaturas e chances recalculam sozinhos.
B4: Área — quão perigoso é o trecho
B5: Área | C5: Quando usar | D5: Evento se d20 ≥ | E5: Mod. intensidade | F5: NP sugerido | G5: Exemplos
B6: Tranquila | C6: Estrada principal, patrulhada, perto de cidades | D6: 17 | E6: -1 | F6: NP 2–4 | G6: Novigrad–Oxenfurt, rotas comerciais de Temeria
B7: Média | C7: Estradas comuns do reino, fazendas e aldeias espaçadas | D7: 14 | E7: 0 | F7: NP 3–5 | G7: Interior de Redânia, Aedirn
B8: Perigosa | C8: Fronteira, floresta densa, pântano, região em guerra | D8: 11 | E8: 1 | F8: NP 4–7 | G8: Velen, margens do Pontar, Brokilon (borda)
B9: Mortal | C9: Ermos, terra amaldiçoada, campo de batalha recente | D9: 8 | E9: 2 | F9: NP 5–9 | G9: Pântanos de Velen, Montanhas Azuis, ruínas élficas
B11: Período do dia — role uma vez por período
B12: Período | C12: Horário | D12: Mod. d20 (acontece?) | E12: Mod. d100 (tipo) | G12: Notas de mesa
B13: Manhã | C13: Amanhecer ao meio-dia | D13: -2 | E13: -10 | G13: Respiro. Bom para social, obstáculos e pistas deixadas durante a noite.
B14: Tarde | C14: Meio-dia ao entardecer | D14: 0 | E14: 0 | G14: Viagem plena. Bandidos e patrulhas; o fim da tarde já traz presságios.
B15: Noite | C15: Entardecer à meia-noite | D15: 2 | E15: 10 | G15: Acampamento, fogueira e vigília. Feras e monstros saem.
B16: Madrugada | C16: Meia-noite ao amanhecer | D16: 3 | E16: 15 | G16: A hora dos espectros. Prefira sinais e pressão antes do combate.
B17: O mod. d100 empurra a rolagem de tipo para baixo (cotidiano) de manhã e para cima (monstros e sobrenatural) de madrugada.
B19: Situação do grupo
B20: Situação | C20: Descrição | D20: Mod. d20 (acontece?)
B21: Na estrada | C21: Viajando ou em pausa curta. | D21: 0
B22: Acampado com fogueira | C22: O fogo afasta feras, mas é visto de longe. | D22: 1
B23: Acampado escondido | C23: Sem fogo: frio e desconforto, mas difícil de achar. | D23: -2
B24: Abrigo seguro | C24: Estalagem, aldeia ou casa. Só acontece algo se for importante. | D24: -6
B26: Atividade da criatura × período (multiplica o peso na aba Criaturas)
B27: Atividade | C27: Manhã | D27: Tarde | E27: Noite | F27: Madrugada
B28: Diurna | C28: 1.5 | D28: 1.5 | E28: 0.5 | F28: 0.25
B29: Noturna | C29: 0.25 | D29: 0.5 | E29: 1.5 | F29: 2
B30: Qualquer | C30: 1 | D30: 1 | E30: 1 | F30: 1
B31: Fator fora do terreno | C31: 0.1 | D31: Criatura fora do terreno dela fica rara (peso × este fator), mas não impossível.
B33: Terreno do trecho
B34: Terreno | C34: Inclui
B35: Estrada | C35: Estradas, campos, fazendas, trigais
B36: Floresta | C36: Bosques, mata fechada, clareiras
B37: Pântano | C37: Pântanos, rios, lagos, margens e costas
B38: Montanha | C38: Montanhas, colinas, desfiladeiros, cavernas
B39: Ruínas | C39: Ruínas, cemitérios, campos de batalha, aldeias abandonadas
B41: Chance de evento por período (na estrada, clima sem modificador)
B42: Área | C42: Manhã | D42: Tarde | E42: Noite | F42: Madrugada | G42: Eventos esperados/dia
B43: Tranquila | C43: =MAX(0,MIN(20,21-($D$6-$D$13)))/20 | D43: =MAX(0,MIN(20,21-($D$6-$D$14)))/20 | E43: =MAX(0,MIN(20,21-($D$6-$D$15)))/20 | F43: =MAX(0,MIN(20,21-($D$6-$D$16)))/20 | G43: =SUM(C43:F43)
B44: Média | C44: =MAX(0,MIN(20,21-($D$7-$D$13)))/20 | D44: =MAX(0,MIN(20,21-($D$7-$D$14)))/20 | E44: =MAX(0,MIN(20,21-($D$7-$D$15)))/20 | F44: =MAX(0,MIN(20,21-($D$7-$D$16)))/20 | G44: =SUM(C44:F44)
B45: Perigosa | C45: =MAX(0,MIN(20,21-($D$8-$D$13)))/20 | D45: =MAX(0,MIN(20,21-($D$8-$D$14)))/20 | E45: =MAX(0,MIN(20,21-($D$8-$D$15)))/20 | F45: =MAX(0,MIN(20,21-($D$8-$D$16)))/20 | G45: =SUM(C45:F45)
B46: Mortal | C46: =MAX(0,MIN(20,21-($D$9-$D$13)))/20 | D46: =MAX(0,MIN(20,21-($D$9-$D$14)))/20 | E46: =MAX(0,MIN(20,21-($D$9-$D$15)))/20 | F46: =MAX(0,MIN(20,21-($D$9-$D$16)))/20 | G46: =SUM(C46:F46)
...

Sheet Clima
B1: Clima (d100 por estação)
B2: Role no início do dia. A cada troca de período role 1d6: no 6 o clima muda (role de novo). Pesos editáveis; as faixas recalculam.
C4: Peso por estação (soma 100) | G4: Faixa no d100
B5: Clima | C5: Primavera | D5: Verão | E5: Outono | F5: Inverno | G5: Primavera | H5: Verão | I5: Outono | J5: Inverno | K5: Mod. d20 | L5: Mod. d100 | M5: Efeito na viagem | N5: Efeito em jogo (M&M) | P5: Ac.Pri | Q5: Ac.Ver | R5: Ac.Out | S5: Ac.Inv | T5: Ac. atual
B6: Céu limpo | C6: 25 | D6: 35 | E6: 15 | F6: 15 | G6: =IF(C6=0,"—",(0+1)&"–"&P6) | H6: =IF(D6=0,"—",(0+1)&"–"&Q6) | I6: =IF(E6=0,"—",(0+1)&"–"&R6) | J6: =IF(F6=0,"—",(0+1)&"–"&S6) | K6: 0 | L6: 0 | M6: Viagem normal, boa visibilidade. | N6: Sem modificadores. | P6: =SUM(C$6:C6) | Q6: =SUM(D$6:D6) | R6: =SUM(E$6:E6) | S6: =SUM(F$6:F6) | T6: =INDEX(P6:S6,MATCH(Painel!$C$8,$C$5:$F$5,0))
B7: Calor intenso | C7: 0 | D7: 18 | E7: 0 | F7: 0 | G7: =IF(C7=0,"—",(P6+1)&"–"&P7) | H7: =IF(D7=0,"—",(Q6+1)&"–"&Q7) | I7: =IF(E7=0,"—",(R6+1)&"–"&R7) | J7: =IF(F7=0,"—",(S6+1)&"–"&S7) | K7: -1 | L7: 0 | M7: Cavalos cansam rápido; água vira prioridade. Bichos se entocam de dia. | N7: Marcha à tarde: Fortitude CD 10 ou Fatigado (CD 15 de armadura pesada). | P7: =SUM(C$6:C7) | Q7: =SUM(D$6:D7) | R7: =SUM(E$6:E7) | S7: =SUM(F$6:F7) | T7: =INDEX(P7:S7,MATCH(Painel!$C$8,$C$5:$F$5,0))
B8: Nublado | C8: 20 | D8: 12 | E8: 25 | F8: 20 | G8: =IF(C8=0,"—",(P7+1)&"–"&P8) | H8: =IF(D8=0,"—",(Q7+1)&"–"&Q8) | I8: =IF(E8=0,"—",(R7+1)&"–"&R8) | J8: =IF(F8=0,"—",(S7+1)&"–"&S8) | K8: 0 | L8: 0 | M8: Luz difusa, dia parece mais curto. | N8: Sem modificadores. | P8: =SUM(C$6:C8) | Q8: =SUM(D$6:D8) | R8: =SUM(E$6:E8) | S8: =SUM(F$6:F8) | T8: =INDEX(P8:S8,MATCH(Painel!$C$8,$C$5:$F$5,0))
B9: Garoa | C9: 15 | D9: 6 | E9: 15 | F9: 0 | G9: =IF(C9=0,"—",(P8+1)&"–"&P9) | H9: =IF(D9=0,"—",(Q8+1)&"–"&Q9) | I9: =IF(E9=0,"—",(R8+1)&"–"&R9) | J9: =IF(F9=0,"—",(S8+1)&"–"&S9) | K9: 0 | L9: 0 | M9: Estrada escorregadia, roupa úmida. | N9: −1 em Percepção (audição); +2 para seguir rastros frescos. | P9: =SUM(C$6:C9) | Q9: =SUM(D$6:D9) | R9: =SUM(E$6:E9) | S9: =SUM(F$6:F9) | T9: =INDEX(P9:S9,MATCH(Painel!$C$8,$C$5:$F$5,0))
B10: Chuva forte | C10: 12 | D10: 8 | E10: 12 | F10: 3 | G10: =IF(C10=0,"—",(P9+1)&"–"&P10) | H10: =IF(D10=0,"—",(Q9+1)&"–"&Q10) | I10: =IF(E10=0,"—",(R9+1)&"–"&R10) | J10: =IF(F10=0,"—",(S9+1)&"–"&S10) | K10: -1 | L10: 0 | M10: Estrada vira lama (viagem 25% mais lenta); rios sobem. | N10: −2 em Percepção; ataques à distância −2; rastros antigos somem; acender fogo: Sobrevivência CD 12. | P10: =SUM(C$6:C10) | Q10: =SUM(D$6:D10) | R10: =SUM(E$6:E10) | S10: =SUM(F$6:F10) | T10: =INDEX(P10:S10,MATCH(Painel!$C$8,$C$5:$F$5,0))
B11: Tempestade | C11: 6 | D11: 10 | E11: 5 | F11: 2 | G11: =IF(C11=0,"—",(P10+1)&"–"&P11) | H11: =IF(D11=0,"—",(Q10+1)&"–"&Q11) | I11: =IF(E11=0,"—",(R10+1)&"–"&R11) | J11: =IF(F11=0,"—",(S10+1)&"–"&S11) | K11: -2 | L11: 0 | M11: Raios e vendaval. Procure abrigo; viagem pela metade. | N11: −5 em Percepção; ataques à distância −5; Fortitude CD 10 por período exposto ou Fatigado. | P11: =SUM(C$6:C11) | Q11: =SUM(D$6:D11) | R11: =SUM(E$6:E11) | S11: =SUM(F$6:F11) | T11: =INDEX(P11:S11,MATCH(Painel!$C$8,$C$5:$F$5,0))
B12: Neblina | C12: 12 | D12: 4 | E12: 15 | F12: 10 | G12: =IF(C12=0,"—",(P11+1)&"–"&P12) | H12: =IF(D12=0,"—",(Q11+1)&"–"&Q12) | I12: =IF(E12=0,"—",(R11+1)&"–"&R12) | J12: =IF(F12=0,"—",(S11+1)&"–"&S12) | K12: 2 | L12: 10 | M12: Visibilidade de poucos metros; sons enganam; fácil se perder. | N12: Camuflagem além de 10 m (−5 em Percepção visual); Sobrevivência CD 12 para não se perder. | P12: =SUM(C$6:C12) | Q12: =SUM(D$6:D12) | R12: =SUM(E$6:E12) | S12: =SUM(F$6:F12) | T12: =INDEX(P12:S12,MATCH(Painel!$C$8,$C$5:$F$5,0))
B13: Ventania | C13: 7 | D13: 7 | E13: 10 | F13: 10 | G13: =IF(C13=0,"—",(P12+1)&"–"&P13) | H13: =IF(D13=0,"—",(Q12+1)&"–"&Q13) | I13: =IF(E13=0,"—",(R12+1)&"–"&R13) | J13: =IF(F13=0,"—",(S12+1)&"–"&S13) | K13: 0 | L13: 0 | M13: Poeira e folhas; fogueira difícil. | N13: Ataques à distância −2; Percepção auditiva −2. | P13: =SUM(C$6:C13) | Q13: =SUM(D$6:D13) | R13: =SUM(E$6:E13) | S13: =SUM(F$6:F13) | T13: =INDEX(P13:S13,MATCH(Painel!$C$8,$C$5:$F$5,0))
B14: Frio intenso | C14: 3 | D14: 0 | E14: 3 | F14: 20 | G14: =IF(C14=0,"—",(P13+1)&"–"&P14) | H14: =IF(D14=0,"—",(Q13+1)&"–"&Q14) | I14: =IF(E14=0,"—",(R13+1)&"–"&R14) | J14: =IF(F14=0,"—",(S13+1)&"–"&S14) | K14: -1 | L14: 0 | M14: Geada; fogo e agasalho à noite são obrigatórios. | N14: Sem agasalho: Fortitude CD 10 por período noturno ou Fatigado. | P14: =SUM(C$6:C14) | Q14: =SUM(D$6:D14) | R14: =SUM(E$6:E14) | S14: =SUM(F$6:F14) | T14: =INDEX(P14:S14,MATCH(Painel!$C$8,$C$5:$F$5,0))
B15: Neve | C15: 0 | D15: 0 | E15: 0 | F15: 15 | G15: =IF(C15=0,"—",(P14+1)&"–"&P15) | H15: =IF(D15=0,"—",(Q14+1)&"–"&Q15) | I15: =IF(E15=0,"—",(R14+1)&"–"&R15) | J15: =IF(F15=0,"—",(S14+1)&"–"&S15) | K15: -1 | L15: 0 | M15: Neve acumulada: viagem 50% mais lenta, rastros muito visíveis. | N15: +5 para seguir rastros; fora da estrada é terreno difícil. | P15: =SUM(C$6:C15) | Q15: =SUM(D$6:D15) | R15: =SUM(E$6:E15) | S15: =SUM(F$6:F15) | T15: =INDEX(P15:S15,MATCH(Painel!$C$8,$C$5:$F$5,0))
B16: Nevasca | C16: 0 | D16: 0 | E16: 0 | F16: 5 | G16: =IF(C16=0,"—",(P15+1)&"–"&P16) | H16: =IF(D16=0,"—",(Q15+1)&"–"&Q16) | I16: =IF(E16=0,"—",(R15+1)&"–"&R16) | J16: =IF(F16=0,"—",(S15+1)&"–"&S16) | K16: -3 | L16: 0 | M16: Branco total; viajar é arriscado. Procure abrigo. | N16: −5 em Percepção; viagem a 1/4; Fortitude CD 15 por período exposto ou Fatigado. | P16: =SUM(C$6:C16) | Q16: =SUM(D$6:D16) | R16: =SUM(E$6:E16) | S16: =SUM(F$6:F16) | T16: =INDEX(P16:S16,MATCH(Painel!$C$8,$C$5:$F$5,0))
B17: Total / conferência | C17: =SUM(C6:C16) | D17: =SUM(D6:D16) | E17: =SUM(E6:E16) | F17: =SUM(F6:F16) | G17: =IF(C17=100,"OK","Soma ≠ 100") | H17: =IF(D17=100,"OK","Soma ≠ 100") | I17: =IF(E17=100,"OK","Soma ≠ 100") | J17: =IF(F17=100,"OK","Soma ≠ 100")
B19: Mod. d20 e d100 entram no Painel: neblina deixa eventos mais prováveis e mais estranhos; tempestade e frio deixam a estrada vazia.

Sheet Tipo de evento
B1: Tipo de evento (d100 + mod. de período e clima)
B2: Os tipos vão do mais cotidiano (topo) ao mais perigoso (base). Quanto mais perigosa a área, mais faixas ficam embaixo.
C4: Peso por área (soma 100) | G4: Faixa no d100
B5: Tipo | C5: Tranquila | D5: Média | E5: Perigosa | F5: Mortal | G5: Tranquila | H5: Média | I5: Perigosa | J5: Mortal | K5: Criatura? | L5: O que é | P5: Ac.Tra | Q5: Ac.Méd | R5: Ac.Per | S5: Ac.Mor | T5: Ac. atual
B6: Encontro social | C6: 35 | D6: 20 | E6: 10 | F6: 5 | G6: =IF(C6=0,"—",(0+1)&"–"&P6) | H6: =IF(D6=0,"—",(0+1)&"–"&Q6) | I6: =IF(E6=0,"—",(0+1)&"–"&R6) | J6: =IF(F6=0,"—",(0+1)&"–"&S6) | K6: — | L6: Gente na estrada: mercadores, viajantes, patrulhas, rumores e ganchos. | P6: =SUM(C$6:C6) | Q6: =SUM(D$6:D6) | R6: =SUM(E$6:E6) | S6: =SUM(F$6:F6) | T6: =INDEX(P6:S6,MATCH(Painel!$C$6,$C$5:$F$5,0))
B7: Obstáculo | C7: 25 | D7: 18 | E7: 12 | F7: 7 | G7: =IF(C7=0,"—",(P6+1)&"–"&P7) | H7: =IF(D7=0,"—",(Q6+1)&"–"&Q7) | I7: =IF(E7=0,"—",(R6+1)&"–"&R7) | J7: =IF(F7=0,"—",(S6+1)&"–"&S7) | K7: — | L7: O caminho ou o equipamento cria um problema: lama, ponte caída, roda quebrada. | P7: =SUM(C$6:C7) | Q7: =SUM(D$6:D7) | R7: =SUM(E$6:E7) | S7: =SUM(F$6:F7) | T7: =INDEX(P7:S7,MATCH(Painel!$C$6,$C$5:$F$5,0))
B8: Descoberta | C8: 18 | D8: 12 | E8: 8 | F8: 6 | G8: =IF(C8=0,"—",(P7+1)&"–"&P8) | H8: =IF(D8=0,"—",(Q7+1)&"–"&Q8) | I8: =IF(E8=0,"—",(R7+1)&"–"&R8) | J8: =IF(F8=0,"—",(S7+1)&"–"&S8) | K8: — | L8: Algo para encontrar: carroça abandonada, ervas, santuário, cadáver com pertences. | P8: =SUM(C$6:C8) | Q8: =SUM(D$6:D8) | R8: =SUM(E$6:E8) | S8: =SUM(F$6:F8) | T8: =INDEX(P8:S8,MATCH(Painel!$C$6,$C$5:$F$5,0))
B9: Pista / presságio | C9: 12 | D9: 15 | E9: 15 | F9: 14 | G9: =IF(C9=0,"—",(P8+1)&"–"&P9) | H9: =IF(D9=0,"—",(Q8+1)&"–"&Q9) | I9: =IF(E9=0,"—",(R8+1)&"–"&R9) | J9: =IF(F9=0,"—",(S8+1)&"–"&S9) | K9: Monstro | L9: Sinal de uma criatura sem ela aparecer. A criatura sorteada é quem deixou o sinal. | P9: =SUM(C$6:C9) | Q9: =SUM(D$6:D9) | R9: =SUM(E$6:E9) | S9: =SUM(F$6:F9) | T9: =INDEX(P9:S9,MATCH(Painel!$C$6,$C$5:$F$5,0))
B10: Humanos hostis | C10: 5 | D10: 13 | E10: 13 | F10: 10 | G10: =IF(C10=0,"—",(P9+1)&"–"&P10) | H10: =IF(D10=0,"—",(Q9+1)&"–"&Q10) | I10: =IF(E10=0,"—",(R9+1)&"–"&R10) | J10: =IF(F10=0,"—",(S9+1)&"–"&S10) | K10: Humano | L10: Bandidos, desertores, caçadores de bruxas, cultistas. | P10: =SUM(C$6:C10) | Q10: =SUM(D$6:D10) | R10: =SUM(E$6:E10) | S10: =SUM(F$6:F10) | T10: =INDEX(P10:S10,MATCH(Painel!$C$6,$C$5:$F$5,0))
B11: Fera | C11: 4 | D11: 12 | E11: 14 | F11: 14 | G11: =IF(C11=0,"—",(P10+1)&"–"&P11) | H11: =IF(D11=0,"—",(Q10+1)&"–"&Q11) | I11: =IF(E11=0,"—",(R10+1)&"–"&R11) | J11: =IF(F11=0,"—",(S10+1)&"–"&S11) | K11: Fera | L11: Animais: lobos, wargs, ursos. | P11: =SUM(C$6:C11) | Q11: =SUM(D$6:D11) | R11: =SUM(E$6:E11) | S11: =SUM(F$6:F11) | T11: =INDEX(P11:S11,MATCH(Painel!$C$6,$C$5:$F$5,0))
B12: Monstro | C12: 1 | D12: 7 | E12: 18 | F12: 28 | G12: =IF(C12=0,"—",(P11+1)&"–"&P12) | H12: =IF(D12=0,"—",(Q11+1)&"–"&Q12) | I12: =IF(E12=0,"—",(R11+1)&"–"&R12) | J12: =IF(F12=0,"—",(S11+1)&"–"&S12) | K12: Monstro | L12: Criaturas do Continente: afogadores, nekkers, carniçais, trolls, grifos... | P12: =SUM(C$6:C12) | Q12: =SUM(D$6:D12) | R12: =SUM(E$6:E12) | S12: =SUM(F$6:F12) | T12: =INDEX(P12:S12,MATCH(Painel!$C$6,$C$5:$F$5,0))
B13: Sobrenatural | C13: 0 | D13: 3 | E13: 10 | F13: 16 | G13: =IF(C13=0,"—",(P12+1)&"–"&P13) | H13: =IF(D13=0,"—",(Q12+1)&"–"&Q13) | I13: =IF(E13=0,"—",(R12+1)&"–"&R13) | J13: =IF(F13=0,"—",(S12+1)&"–"&S13) | K13: Sobrenatural | L13: Espectros, megeras, leshen, maldições e barganhas. | P13: =SUM(C$6:C13) | Q13: =SUM(D$6:D13) | R13: =SUM(E$6:E13) | S13: =SUM(F$6:F13) | T13: =INDEX(P13:S13,MATCH(Painel!$C$6,$C$5:$F$5,0))
B14: Total / conferência | C14: =SUM(C6:C13) | D14: =SUM(D6:D13) | E14: =SUM(E6:E13) | F14: =SUM(F6:F13) | G14: =IF(C14=100,"OK","Soma ≠ 100") | H14: =IF(D14=100,"OK","Soma ≠ 100") | I14: =IF(E14=100,"OK","Soma ≠ 100") | J14: =IF(F14=100,"OK","Soma ≠ 100")
B16: Rolagem final = d100 + mod. do período + mod. do clima, limitada entre 1 e 100. Ex.: Manhã −10, Madrugada +15, Neblina +10.

Sheet Eventos
B1: Eventos (d6 dentro do tipo)
B2: Se o evento não combinar com o período ou o lugar, role o d6 de novo. Pode reescrever à vontade.
A4: Chave | B4: Tipo | C4: d6 | D4: Evento | E4: Descrição inicial | F4: Opções do jogador | G4: Reviravolta / nota do mestre | H4: Melhor período
A5: =B5&"|"&C5 | B5: Encontro social | C5: 1 | D5: Mercador ambulante | E5: Carroça coberta, mula teimosa e um mercador que fala demais. | F5: Comprar, vender, trocar rumores, barganhar. | G5: Um item à venda tem má fama; um rumor aponta para um contrato. | H5: Manhã / Tarde
A6: =B6&"|"&C6 | B6: Encontro social | C6: 2 | D6: Viajantes pedem ajuda | E6: Uma família ou viajante ferido pede escolta ou carona. | F6: Ajudar, recusar, negociar, investigar a história. | G6: Gente sincera — ou alguém esconde uma mordida, uma maldição ou uma dívida. | H6: Manhã / Tarde
A7: =B7&"|"&C7 | B7: Encontro social | C7: 3 | D7: Patrulha do reino | E7: Soldados param o grupo, pedem documentos e perguntam por um desertor. | F7: Mostrar papéis, subornar, blefar, colaborar. | G7: O desertor está escondido logo adiante; ou os soldados querem só um 'pedágio'. | H7: Manhã / Tarde
A8: =B8&"|"&C8 | B8: Encontro social | C8: 4 | D8: Bardo e rumores | E8: Um menestrel na beira da estrada canta sobre um monstro da região. | F8: Ouvir, pagar por detalhes, seguir junto. | G8: A canção exagera — ou acerta em algo que ninguém devia saber. | H8: Tarde / Noite
A9: =B9&"|"&C9 | B9: Encontro social | C9: 5 | D9: Caçadores desconfiados | E9: Dois caçadores perguntam para onde o grupo vai. | F9: Conversar, trocar informações, perceber contradições. | G9: Podem ser caçadores legítimos ou batedores de bandidos. | H9: Manhã / Tarde
A10: =B10&"|"&C10 | B10: Encontro social | C10: 6 | D10: Aviso de contrato | E10: Um poste ou árvore com aviso pregado: recompensa por um monstro. | F10: Ler, arrancar e levar, ignorar. | G10: O contratante paga mal, mente sobre o monstro, ou já contratou outro bruxo. | H10: Qualquer
A11: =B11&"|"&C11 | B11: Obstáculo | C11: 1 | D11: Roda quebrada / cavalo manco | E11: A roda racha num buraco ou o cavalo começa a mancar. | F11: Reparar, improvisar, perder tempo, seguir a pé. | G11: Quem ajudar pede algo em troca; a pedra no casco foi colocada de propósito? | H11: Qualquer
A12: =B12&"|"&C12 | B12: Obstáculo | C12: 2 | D12: Travessia alagada | E12: A ponte caiu ou o vau subiu com a chuva. | F12: Procurar outro ponto, consertar, atravessar com risco, esperar. | G12: Água turva e restos na margem: afogadores por perto. | H12: Qualquer
A13: =B13&"|"&C13 | B13: Obstáculo | C13: 3 | D13: Árvore caída | E13: Um tronco enorme bloqueia a estrada. | F13: Cortar, contornar pelo mato, puxar com o cavalo. | G13: Corte limpo de machado: alguém derrubou de propósito (emboscada?). | H13: Qualquer
A14: =B14&"|"&C14 | B14: Obstáculo | C14: 4 | D14: Caminho perdido | E14: A estrada se divide e nenhuma placa ajuda. | F14: Sobrevivência para se orientar, perguntar, voltar. | G14: Errar custa um período — e leva a uma área mais perigosa. | H14: Qualquer
A15: =B15&"|"&C15 | B15: Obstáculo | C15: 5 | D15: Atoleiro | E15: A carroça afunda na lama até o eixo. | F15: Empurrar (Força), descarregar, procurar ajuda. | G15: Lama demais para a estação: há algo represando o riacho acima. | H15: Manhã / Tarde
A16: =B16&"|"&C16 | B16: Obstáculo | C16: 6 | D16: Deslizamento | E16: Pedras e terra soltas bloqueiam ou ameaçam o trecho. | F16: Escalar, limpar, esperar, desviar. | G16: O barulho atrai algo ou revela uma entrada de caverna. | H16: Qualquer
... A52: =B52&"|"&C52 | B52: Sobrenatural | C52: 6 | D52: Proposta de barganha | E52: Uma voz ou figura oferece ajuda em troca de um favor. | F52: Aceitar, recusar, negociar os termos. | G52: Todo preço sobrenatural cobra juros. | H52: Qualquer

Sheet Criaturas
B1: Criaturas do Continente (a partir do nosso bestiário)
B2: Cada criatura de The Witcher usa uma ficha base de dados/bestiario/fantasia (ou um arquétipo do gerador de NPCs). Pesos por área são editáveis.
I4: Peso por área | N4: Sorteio atual (automático)
A5: Categoria | B5: Criatura (The Witcher) | C5: Ficha base | D5: Arquivo (bestiario/fantasia/) | E5: NP | F5: Atividade | G5: Terrenos | H5: Grupo típico | I5: Tranquila | J5: Média | K5: Perigosa | L5: Mortal | M5: Adaptação / como jogar | N5: Fator período | O5: Fator terreno | P5: Peso efetivo | Q5: Acumulado | R5: Chance agora
A6: Humano | B6: Bandidos de estrada | C6: Arquétipo: Bandido de estrada | D6: Gerador de NPC | E6: 3–5 | F6: Diurna | G6: Estrada, Floresta | H6: 3–6 capangas + chefe (NP+1) | I6: 6 | J6: 6 | K6: 5 | L6: 3 | M6: Negociam, blefam e fogem ao perder metade do bando. | N6: =INDEX(Ajustes!$C$28:$F$30,MATCH(F6,Ajustes!$B$28:$B$30,0),MATCH(Painel!$C$7,Ajustes!$C$27:$F$27,0)) | O6: =IF(OR(G6="Qualquer",ISNUMBER(SEARCH(Painel!$C$9,G6))),1,Ajustes!$C$31) | P6: =IF(A6=Painel!$M$17,INDEX(I6:L6,MATCH(Painel!$C$6,$I$5:$L$5,0))*N6*O6,0) | Q6: =SUM($P$6:P6) | R6: =IF(MAX($Q$6:$Q$38)=0,0,P6/MAX($Q$6:$Q$38))
A7: Humano | B7: Desertores / mercenários | C7: Arquétipo: Soldado do reino | D7: Gerador de NPC | E7: 4–6 | F7: Qualquer | G7: Estrada, Floresta, Montanha | H7: 2–5 | I7: 2 | J7: 4 | K7: 5 | L7: 4 | M7: Famintos e com medo da forca; viram aliados por comida ou silêncio. | N7: =INDEX(Ajustes!$C$28:$F$30,MATCH(F7,Ajustes!$B$28:$B$30,0),MATCH(Painel!$C$7,Ajustes!$C$27:$F$27,0)) | O7: =IF(OR(G7="Qualquer",ISNUMBER(SEARCH(Painel!$C$9,G7))),1,Ajustes!$C$31) | P7: =IF(A7=Painel!$M$17,INDEX(I7:L7,MATCH(Painel!$C$6,$I$5:$L$5,0))*N7*O7,0) | Q7: =SUM($P$6:P7) | R7: =IF(MAX($Q$6:$Q$38)=0,0,P7/MAX($Q$6:$Q$38))
A8: Humano | B8: Patrulha hostil (Nilfgaard ou reino rival) | C8: Arquétipo: Soldado do reino; oficial = Hobgoblin Capitão | D8: goblins/hobgoblin_capitao.json | E8: 5–7 | F8: Diurna | G8: Estrada | H8: 4–8 + oficial | I8: 1 | J8: 2 | K8: 4 | L8: 2 | M8: Querem papéis, suborno ou um culpado. Lutar contra eles tem consequência política. | N8: =INDEX(Ajustes!$C$28:$F$30,MATCH(F8,Ajustes!$B$28:$B$30,0),MATCH(Painel!$C$7,Ajustes!$C$27:$F$27,0)) | O8: =IF(OR(G8="Qualquer",ISNUMBER(SEARCH(Painel!$C$9,G8))),1,Ajustes!$C$31) | P8: =IF(A8=Painel!$M$17,INDEX(I8:L8,MATCH(Painel!$C$6,$I$5:$L$5,0))*N8*O8,0) | Q8: =SUM($P$6:P8) | R8: =IF(MAX($Q$6:$Q$38)=0,0,P8/MAX($Q$6:$Q$38))
A9: Humano | B9: Caçadores de bruxas | C9: Arquétipo: Guarda da cidade; líder = Soldado do reino | D9: Gerador de NPC | E9: 4–6 | F9: Diurna | G9: Estrada, Ruínas | H9: 3–5 | I9: 1 | J9: 2 | K9: 3 | L9: 2 | M9: Perseguem magos, não-humanos e mutantes — bruxos inclusos. | N9: =INDEX(Ajustes!$C$28:$F$30,MATCH(F9,Ajustes!$B$28:$B$30,0),MATCH(Painel!$C$7,Ajustes!$C$27:$F$27,0)) | O9: =IF(OR(G9="Qualquer",ISNUMBER(SEARCH(Painel!$C$9,G9))),1,Ajustes!$C$31) | P9: =IF(A9=Painel!$M$17,INDEX(I9:L9,MATCH(Painel!$C$6,$I$5:$L$5,0))*N9*O9,0) | Q9: =SUM($P$6:P9) | R9: =IF(MAX($Q$6:$Q$38)=0,0,P9/MAX($Q$6:$Q$38))
A10: Humano | B10: Caçador de recompensas / assassino | C10: Arquétipo: Assassino de aluguel | D10: Gerador de NPC | E10: 6–8 | F10: Noturna | G10: Qualquer | H10: 1–2 | I10: 1 | J10: 1 | K10: 2 | L10: 2 | M10: Alguém pagou por um nome. Ataca no acampamento. | N10: =INDEX(Ajustes!$C$28:$F$30,MATCH(F10,Ajustes!$B$28:$B$30,0),MATCH(Painel!$C$7,Ajustes!$C$27:$F$27,0)) | O10: =IF(OR(G10="Qualquer",ISNUMBER(SEARCH(Painel!$C$9,G10))),1,Ajustes!$C$31) | P10: =IF(A10=Painel!$M$17,INDEX(I10:L10,MATCH(Painel!$C$6,$I$5:$L$5,0))*N10*O10,0) | Q10: =SUM($P$6:P10) | R10: =IF(MAX($Q$6:$Q$38)=0,0,P10/MAX($Q$6:$Q$38))
A11: Humano | B11: Cultistas | C11: Arquétipo: Cultista | D11: Gerador de NPC | E11: 3–6 | F11: Noturna | G11: Floresta, Ruínas, Pântano | H11: 3–8 | I11: 0 | J11: 1 | K11: 2 | L11: 4 | M11: Ritual em andamento; podem servir a um leshen ou demônio. | N11: =INDEX(Ajustes!$C$28:$F$30,MATCH(F11,Ajustes!$B$28:$B$30,0),MATCH(Painel!$C$7,Ajustes!$C$27:$F$27,0)) | O11: =IF(OR(G11="Qualquer",ISNUMBER(SEARCH(Painel!$C$9,G11))),1,Ajustes!$C$31) | P11: =IF(A11=Painel!$M$17,INDEX(I11:L11,MATCH(Painel!$C$6,$I$5:$L$5,0))*N11*O11,0) | Q11: =SUM($P$6:P11) | R11: =IF(MAX($Q$6:$Q$38)=0,0,P11/MAX($Q$6:$Q$38))
A12: Humano | B12: Mago renegado | C12: Hobgoblin Conjurador de Guerra (reskin humano) | D12: goblins/hobgoblin_conjurador.json | E12: 6 | F12: Qualquer | G12: Ruínas, Montanha | H12: 1 + 1–3 guarda-costas | I12: 0 | J12: 0 | K12: 1 | L12: 2 | M12: Fugitivo da Irmandade. Troque o fogo de guerra por magia variada. | N12: =INDEX(Ajustes!$C$28:$F$30,MATCH(F12,Ajustes!$B$28:$B$30,0),MATCH(Painel!$C$7,Ajustes!$C$27:$F$27,0)) | O12: =IF(OR(G12="Qualquer",ISNUMBER(SEARCH(Painel!$C$9,G12))),1,Ajustes!$C$31) | P12: =IF(A12=Painel!$M$17,INDEX(I12:L12,MATCH(Painel!$C$6,$I$5:$L$5,0))*N12*O12,0) | Q12: =SUM($P$6:P12) | R12: =IF(MAX($Q$6:$Q$38)=0,0,P12/MAX($Q$6:$Q$38))
A13: Fera | B13: Lobos | C13: Lobo | D13: feras/lobo.json | E13: 3 | F13: Noturna | G13: Floresta, Montanha, Estrada | H13: Matilha de 3–6 | I13: 6 | J13: 6 | K13: 5 | L13: 4 | M13: Testam o grupo; fogem com fogo ou se o mais forte cair. | N13: =INDEX(Ajustes!$C$28:$F$30,MATCH(F13,Ajustes!$B$28:$B$30,0),MATCH(Painel!$C$7,Ajustes!$C$27:$F$27,0)) | O13: =IF(OR(G13="Qualquer",ISNUMBER(SEARCH(Painel!$C$9,G13))),1,Ajustes!$C$31) | P13: =IF(A13=Painel!$M$17,INDEX(I13:L13,MATCH(Painel!$C$6,$I$5:$L$5,0))*N13*O13,0) | Q13: =SUM($P$6:P13) | R13: =IF(MAX($Q$6:$Q$38)=0,0,P13/MAX($Q$6:$Q$38))
A14: Fera | B14: Warg (lobo alfa) | C14: Lobo Atroz | D14: feras/lobo_atroz.json | E14: 5 | F14: Noturna | G14: Floresta, Montanha | H14: 1 + 2–4 lobos | I14: 0 | J14: 1 | K14: 3 | L14: 4 | M14: Lidera a matilha; esperto demais para um lobo comum. | N14: =INDEX(Ajustes!$C$28:$F$30,MATCH(F14,Ajustes!$B$28:$B$30,0),MATCH(Painel!$C$7,Ajustes!$C$27:$F$27,0)) | O14: =IF(OR(G14="Qualquer",ISNUMBER(SEARCH(Painel!$C$9,G14))),1,Ajustes!$C$31) | P14: =IF(A14=Painel!$M$17,INDEX(I14:L14,MATCH(Painel!$C$6,$I$5:$L$5,0))*N14*O14,0) | Q14: =SUM($P$6:P14) | R14: =IF(MAX($Q$6:$Q$38)=0,0,P14/MAX($Q$6:$Q$38))
A15: Fera | B15: Urso | C15: Urso Marrom | D15: feras/urso.json | E15: 6 | F15: Diurna | G15: Floresta, Montanha, Pântano | H15: 1 | I15: 2 | J15: 3 | K15: 3 | L15: 3 | M15: Defende território ou filhotes; recuar quase sempre resolve. | N15: =INDEX(Ajustes!$C$28:$F$30,MATCH(F15,Ajustes!$B$28:$B$30,0),MATCH(Painel!$C$7,Ajustes!$C$27:$F$27,0)) | O15: =IF(OR(G15="Qualquer",ISNUMBER(SEARCH(Painel!$C$9,G15))),1,Ajustes!$C$31) | P15: =IF(A15=Painel!$M$17,INDEX(I15:L15,MATCH(Painel!$C$6,$I$5:$L$5,0))*N15*O15,0) | Q15: =SUM($P$6:P15) | R15: =IF(MAX($Q$6:$Q$38)=0,0,P15/MAX($Q$6:$Q$38))
A16: Monstro | B16: Afogadores | C16: Zumbi (+ Natação, + Velocidade 1, sem lentidão) | D16: mortos_vivos/zumbi.json | E16: 2–3 | F16: Noturna | G16: Pântano | H16: 2–5 | I16: 3 | J16: 5 | K16: 5 | L16: 4 | M16: Só perto de água. Longe dela, troque por Carniçais. | N16: =INDEX(Ajustes!$C$28:$F$30,MATCH(F16,Ajustes!$B$28:$B$30,0),MATCH(Painel!$C$7,Ajustes!$C$27:$F$27,0)) | O16: =IF(OR(G16="Qualquer",ISNUMBER(SEARCH(Painel!$C$9,G16))),1,Ajustes!$C$31) | P16: =IF(A16=Painel!$M$17,INDEX(I16:L16,MATCH(Painel!$C$6,$I$5:$L$5,0))*N16*O16,0) | Q16: =SUM($P$6:P16) | R16: =IF(MAX($Q$6:$Q$38)=0,0,P16/MAX($Q$6:$Q$38))
A17: Monstro | B17: Nekkers | C17: Goblin Saqueador (guerreiros: Goblin Guerreiro) | D17: goblins/goblin_saqueador.json | E17: 2–3 | F17: Noturna | G17: Floresta, Montanha | H17: 4–8 | I17: 2 | J17: 4 | K17: 5 | L17: 4 | M17: Saem de túneis, atacam em bando e fogem. Destruir o ninho resolve. | N17: =INDEX(Ajustes!$C$28:$F$30,MATCH(F17,Ajustes!$B$28:$B$30,0),MATCH(Painel!$C$7,Ajustes!$C$27:$F$27,0)) | O17: =IF(OR(G17="Qualquer",ISNUMBER(SEARCH(Painel!$C$9,G17))),1,Ajustes!$C$31) | P17: =IF(A17=Painel!$M$17,INDEX(I17:L17,MATCH(Painel!$C$6,$I$5:$L$5,0))*N17*O17,0) | Q17: =SUM($P$6:P17) | R17: =IF(MAX($Q$6:$Q$38)=0,0,P17/MAX($Q$6:$Q$38))
... A38: Sobrenatural | B38: Demônio invocado | C38: Demônio Guerreiro | D38: sobrenatural/demonio_guerreiro.json | E38: 6 | F38: Noturna | G38: Ruínas, Floresta | H38: 1 + cultistas | I38: 0 | J38: 0 | K38: 1 | L38: 2 | M38: Círculo de invocação; os cultistas são a pista. | N38: =INDEX(Ajustes!$C$28:$F$30,MATCH(F38,Ajustes!$B$28:$B$30,0),MATCH(Painel!$C$7,Ajustes!$C$27:$F$27,0)) | O38: =IF(OR(G38="Qualquer",ISNUMBER(SEARCH(Painel!$C$9,G38))),1,Ajustes!$C$31) | P38: =IF(A38=Painel!$M$17,INDEX(I38:L38,MATCH(Painel!$C$6,$I$5:$L$5,0))*N38*O38,0) | Q38: =SUM($P$6:P38) | R38: =IF(MAX($Q$6:$Q$38)=0,0,P38/MAX($Q$6:$Q$38))
A40: Como funciona o sorteio: só entram as criaturas da categoria do evento. Peso da área × fator do período (atividade) × fator do terreno. O d100 escolhe proporcionalmente; 'Chance agora' mostra as probabilidades da situação atual do Painel.
A41: Fichas que ficaram de fora (não combinam com o Continente): goblins de areia, elétrico, quebra-gelo, ventanias, tóxico, arqueiro e xamã; bugbear brigão; hobgoblin soldado (use se quiser soldados de elite de Nilfgaard); múmia; esqueletos; cavalo de guerra (é montaria).

Sheet Intensidade
B1: Intensidade do encontro (d6 + mod. da área)
B2: Só quando aparece criatura ou humanos hostis. Tranquila −1, Média 0, Perigosa +1, Mortal +2 (aba Ajustes).
B4: Total | C4: Resultado | D4: Como interpretar | E4: Com personagem solo
B5: 1 | C5: Só sinais | D5: Está longe ou evita o grupo. Deixa rastros, sons ou restos. | E5: Ótimo para tensão; nenhum teste obrigatório.
B6: 2 | C6: Avistamento | D6: Percebe o grupo e observa à distância. Furtividade, Intimidação ou mudar de rota evitam o confronto. | E6: Deixe o jogador escolher se quer o combate.
B7: 3 | C7: Encontro menor | D7: Mínimo do grupo típico, ou um indivíduo jovem ou ferido. | E7: Combate curto e vencível.
B8: 4 | C8: Encontro padrão | D8: Grupo típico, sem vantagens especiais. | E8: Use o grupo típico como teto.
B9: 5 | C9: No terreno dela | D9: Grupo típico com vantagem de terreno: água, mato alto, escuridão. | E9: Recuar para terreno aberto deve ser uma saída real.
B10: 6 | C10: Grupo grande | D10: Máximo do grupo típico, ou reforço chega na 3ª rodada. | E10: Troque inimigos extras por pressão: perseguição, cerco, fuga.
B11: 7 | C11: Emboscada | D11: Surpreende o grupo (rodada de surpresa) a menos que alguém passe em Percepção CD 15. | E11: Surpresa sim; dano extra não.
B12: 8+ | C12: Emboscada + complicação | D12: Como 7, e algo piora: cavalo foge, carga em risco, ou uma segunda ameaça observa. | E12: A complicação é o problema; o inimigo continua do tamanho padrão.
